<?xml version="1.0" ?>
<robot name="spiro_arm">
  <link name="base_link">
    <visual>
      <geometry>
        <cylinder length="0.04" radius="0.015"/>
      </geometry>
      <origin xyz="0 0 0.02" rpy="0 0 0"/>
      <material name="white"><color rgba="0.9 0.9 0.9 1"/></material>
    </visual>
    <collision>
      <geometry>
        <cylinder length="0.04" radius="0.015"/>
      </geometry>
      <origin xyz="0 0 0.02" rpy="0 0 0"/>
    </collision>
    <inertial>
      <mass value="0.02"/>
      <origin xyz="0 0 0.02"/>
      <inertia ixx="0.00001" ixy="0" ixz="0" iyy="0.00001" iyz="0" izz="0.00001"/>
    </inertial>
  </link>
  <!-- 10 segments -->
  <joint name="joint1" type="revolute">
    <parent link="base_link"/>
    <child link="link1"/>
    <origin xyz="0 0 0.04" rpy="0 0 0"/>
    <axis xyz="0 1 0"/>
    <limit lower="-1.57" upper="1.57" effort="5" velocity="2"/>
  </joint>
  <link name="link1">
    <visual>
      <geometry>
        <cylinder length="0.04" radius="0.015"/>
      </geometry>
      <origin xyz="0 0 0.02" rpy="0 0 0"/>
      <material name="white"><color rgba="0.9 0.9 0.9 1"/></material>
    </visual>
    <collision>
      <geometry>
        <cylinder length="0.04" radius="0.015"/>
      </geometry>
      <origin xyz="0 0 0.02" rpy="0 0 0"/>
    </collision>
    <inertial>
      <mass value="0.02"/>
      <origin xyz="0 0 0.02"/>
      <inertia ixx="0.00001" ixy="0" ixz="0" iyy="0.00001" iyz="0" izz="0.00001"/>
    </inertial>
  </link>
  <joint name="joint2" type="revolute">
    <parent link="link1"/>
    <child link="link2"/>
    <origin xyz="0 0 0.04" rpy="0 0 0"/>
    <axis xyz="0 1 0"/>
    <limit lower="-1.57" upper="1.57" effort="5" velocity="2"/>
  </joint>
  <link name="link2">
    <visual>
      <geometry>
        <cylinder length="0.04" radius="0.015"/>
      </geometry>
      <origin xyz="0 0 0.02" rpy="0 0 0"/>
      <material name="white"><color rgba="0.9 0.9 0.9 1"/></material>
    </visual>
    <collision>
      <geometry>
        <cylinder length="0.04" radius="0.015"/>
      </geometry>
      <origin xyz="0 0 0.02" rpy="0 0 0"/>
    </collision>
    <inertial>
      <mass value="0.02"/>
      <origin xyz="0 0 0.02"/>
      <inertia ixx="0.00001" ixy="0" ixz="0" iyy="0.00001" iyz="0" izz="0.00001"/>
    </inertial>
  </link>
  <joint name="joint3" type="revolute">
    <parent link="link2"/>
    <child link="link3"/>
    <origin xyz="0 0 0.04" rpy="0 0 0"/>
    <axis xyz="0 1 0"/>
    <limit lower="-1.57" upper="1.57" effort="5" velocity="2"/>
  </joint>
  <link name="link3">
    <visual>
      <geometry>
        <cylinder length="0.04" radius="0.015"/>
      </geometry>
      <origin xyz="0 0 0.02" rpy="0 0 0"/>
      <material name="white"><color rgba="0.9 0.9 0.9 1"/></material>
    </visual>
    <collision>
      <geometry>
        <cylinder length="0.04" radius="0.015"/>
      </geometry>
      <origin xyz="0 0 0.02" rpy="0 0 0"/>
    </collision>
    <inertial>
      <mass value="0.02"/>
      <origin xyz="0 0 0.02"/>
      <inertia ixx="0.00001" ixy="0" ixz="0" iyy="0.00001" iyz="0" izz="0.00001"/>
    </inertial>
  </link>
  <joint name="joint4" type="revolute">
    <parent link="link3"/>
    <child link="link4"/>
    <origin xyz="0 0 0.04" rpy="0 0 0"/>
    <axis xyz="0 1 0"/>
    <limit lower="-1.57" upper="1.57" effort="5" velocity="2"/>
  </joint>
  <link name="link4">
    <visual>
      <geometry>
        <cylinder length="0.04" radius="0.015"/>
      </geometry>
      <origin xyz="0 0 0.02" rpy="0 0 0"/>
      <material name="white"><color rgba="0.9 0.9 0.9 1"/></material>
    </visual>
    <collision>
      <geometry>
        <cylinder length="0.04" radius="0.015"/>
      </geometry>
      <origin xyz="0 0 0.02" rpy="0 0 0"/>
    </collision>
    <inertial>
      <mass value="0.02"/>
      <origin xyz="0 0 0.02"/>
      <inertia ixx="0.00001" ixy="0" ixz="0" iyy="0.00001" iyz="0" izz="0.00001"/>
    </inertial>
  </link>
  <joint name="joint5" type="revolute">
    <parent link="link4"/>
    <child link="link5"/>
    <origin xyz="0 0 0.04" rpy="0 0 0"/>
    <axis xyz="0 1 0"/>
    <limit lower="-1.57" upper="1.57" effort="5" velocity="2"/>
  </joint>
  <link name="link5">
    <visual>
      <geometry>
        <cylinder length="0.04" radius="0.015"/>
      </geometry>
      <origin xyz="0 0 0.02" rpy="0 0 0"/>
      <material name="white"><color rgba="0.9 0.9 0.9 1"/></material>
    </visual>
    <collision>
      <geometry>
        <cylinder length="0.04" radius="0.015"/>
      </geometry>
      <origin xyz="0 0 0.02" rpy="0 0 0"/>
    </collision>
    <inertial>
      <mass value="0.02"/>
      <origin xyz="0 0 0.02"/>
      <inertia ixx="0.00001" ixy="0" ixz="0" iyy="0.00001" iyz="0" izz="0.00001"/>
    </inertial>
  </link>
  <joint name="joint6" type="revolute">
    <parent link="link5"/>
    <child link="link6"/>
    <origin xyz="0 0 0.04" rpy="0 0 0"/>
    <axis xyz="0 1 0"/>
    <limit lower="-1.57" upper="1.57" effort="5" velocity="2"/>
  </joint>
  <link name="link6">
    <visual>
      <geometry>
        <cylinder length="0.04" radius="0.015"/>
      </geometry>
      <origin xyz="0 0 0.02" rpy="0 0 0"/>
      <material name="white"><color rgba="0.9 0.9 0.9 1"/></material>
    </visual>
    <collision>
      <geometry>
        <cylinder length="0.04" radius="0.015"/>
      </geometry>
      <origin xyz="0 0 0.02" rpy="0 0 0"/>
    </collision>
    <inertial>
      <mass value="0.02"/>
      <origin xyz="0 0 0.02"/>
      <inertia ixx="0.00001" ixy="0" ixz="0" iyy="0.00001" iyz="0" izz="0.00001"/>
    </inertial>
  </link>
  <joint name="joint7" type="revolute">
    <parent link="link6"/>
    <child link="link7"/>
    <origin xyz="0 0 0.04" rpy="0 0 0"/>
    <axis xyz="0 1 0"/>
    <limit lower="-1.57" upper="1.57" effort="5" velocity="2"/>
  </joint>
  <link name="link7">
    <visual>
      <geometry>
        <cylinder length="0.04" radius="0.015"/>
      </geometry>
      <origin xyz="0 0 0.02" rpy="0 0 0"/>
      <material name="white"><color rgba="0.9 0.9 0.9 1"/></material>
    </visual>
    <collision>
      <geometry>
        <cylinder length="0.04" radius="0.015"/>
      </geometry>
      <origin xyz="0 0 0.02" rpy="0 0 0"/>
    </collision>
    <inertial>
      <mass value="0.02"/>
      <origin xyz="0 0 0.02"/>
      <inertia ixx="0.00001" ixy="0" ixz="0" iyy="0.00001" iyz="0" izz="0.00001"/>
    </inertial>
  </link>
  <joint name="joint8" type="revolute">
    <parent link="link7"/>
    <child link="link8"/>
    <origin xyz="0 0 0.04" rpy="0 0 0"/>
    <axis xyz="0 1 0"/>
    <limit lower="-1.57" upper="1.57" effort="5" velocity="2"/>
  </joint>
  <link name="link8">
    <visual>
      <geometry>
        <cylinder length="0.04" radius="0.015"/>
      </geometry>
      <origin xyz="0 0 0.02" rpy="0<!-- filepath: models/spiro_arm.urdf -->
<?xml version="1.0" ?>
<robot name="spiro_arm">
  <link name="base_link">
    <visual>
      <geometry>
        <cylinder length="0.04" radius="0.015"/>
      </geometry>
      <origin xyz="0 0 0.02" rpy="0 0 0"/>
      <material name="white"><color rgba="0.9 0.9 0.9 1"/></material>
    </visual>
    <collision>
      <geometry>
        <cylinder length="0.04" radius="0.015"/>
      </geometry>
      <origin xyz="0 0 0.02" rpy="0 0 0"/>
    </collision>
    <inertial>
      <mass value="0.02"/>
      <origin xyz="0 0 0.02"/>
      <inertia ixx="0.00001" ixy="0" ixz="0" iyy="0.00001" iyz="0" izz="0.00001"/>
    </inertial>
  </link>
  <!-- 10 segments -->
  <joint name="joint1" type="revolute">
    <parent link="base_link"/>
    <child link="link1"/>
    <origin xyz="0 0 0.04" rpy="0 0 0"/>
    <axis xyz="0 1 0"/>
    <limit lower="-1.57" upper="1.57" effort="5" velocity="2"/>
  </joint>
  <link name="link1">
    <visual>
      <geometry>
        <cylinder length="0.04" radius="0.015"/>
      </geometry>
      <origin xyz="0 0 0.02" rpy="0 0 0"/>
      <material name="white"><color rgba="0.9 0.9 0.9 1"/></material>
    </visual>
    <collision>
      <geometry>
        <cylinder length="0.04" radius="0.015"/>
      </geometry>
      <origin xyz="0 0 0.02" rpy="0 0 0"/>
    </collision>
    <inertial>
      <mass value="0.02"/>
      <origin xyz="0 0 0.02"/>
      <inertia ixx="0.00001" ixy="0" ixz="0" iyy="0.00001" iyz="0" izz="0.00001"/>
    </inertial>
  </link>
  <joint name="joint2" type="revolute">
    <parent link="link1"/>
    <child link="link2"/>
    <origin xyz="0 0 0.04" rpy="0 0 0"/>
    <axis xyz="0 1 0"/>
    <limit lower="-1.57" upper="1.57" effort="5" velocity="2"/>
  </joint>
  <link name="link2">
    <visual>
      <geometry>
        <cylinder length="0.04" radius="0.015"/>
      </geometry>
      <origin xyz="0 0 0.02" rpy="0 0 0"/>
      <material name="white"><color rgba="0.9 0.9 0.9 1"/></material>
    </visual>
    <collision>
      <geometry>
        <cylinder length="0.04" radius="0.015"/>
      </geometry>
      <origin xyz="0 0 0.02" rpy="0 0 0"/>
    </collision>
    <inertial>
      <mass value="0.02"/>
      <origin xyz="0 0 0.02"/>
      <inertia ixx="0.00001" ixy="0" ixz="0" iyy="0.00001" iyz="0" izz="0.00001"/>
    </inertial>
  </link>
  <joint name="joint3" type="revolute">
    <parent link="link2"/>
    <child link="link3"/>
    <origin xyz="0 0 0.04" rpy="0 0 0"/>
    <axis xyz="0 1 0"/>
    <limit lower="-1.57" upper="1.57" effort="5" velocity="2"/>
  </joint>
  <link name="link3">
    <visual>
      <geometry>
        <cylinder length="0.04" radius="0.015"/>
      </geometry>
      <origin xyz="0 0 0.02" rpy="0 0 0"/>
      <material name="white"><color rgba="0.9 0.9 0.9 1"/></material>
    </visual>
    <collision>
      <geometry>
        <cylinder length="0.04" radius="0.015"/>
      </geometry>
      <origin xyz="0 0 0.02" rpy="0 0 0"/>
    </collision>
    <inertial>
      <mass value="0.02"/>
      <origin xyz="0 0 0.02"/>
      <inertia ixx="0.00001" ixy="0" ixz="0" iyy="0.00001" iyz="0" izz="0.00001"/>
    </inertial>
  </link>
  <joint name="joint4" type="revolute">
    <parent link="link3"/>
    <child link="link4"/>
    <origin xyz="0 0 0.04" rpy="0 0 0"/>
    <axis xyz="0 1 0"/>
    <limit lower="-1.57" upper="1.57" effort="5" velocity="2"/>
  </joint>
  <link name="link4">
    <visual>
      <geometry>
        <cylinder length="0.04" radius="0.015"/>
      </geometry>
      <origin xyz="0 0 0.02" rpy="0 0 0"/>
      <material name="white"><color rgba="0.9 0.9 0.9 1"/></material>
    </visual>
    <collision>
      <geometry>
        <cylinder length="0.04" radius="0.015"/>
      </geometry>
      <origin xyz="0 0 0.02" rpy="0 0 0"/>
    </collision>
    <inertial>
      <mass value="0.02"/>
      <origin xyz="0 0 0.02"/>
      <inertia ixx="0.00001" ixy="0" ixz="0" iyy="0.00001" iyz="0" izz="0.00001"/>
    </inertial>
  </link>
  <joint name="joint5" type="revolute">
    <parent link="link4"/>
    <child link="link5"/>
    <origin xyz="0 0 0.04" rpy="0 0 0"/>
    <axis xyz="0 1 0"/>
    <limit lower="-1.57" upper="1.57" effort="5" velocity="2"/>
  </joint>
  <link name="link5">
    <visual>
      <geometry>
        <cylinder length="0.04" radius="0.015"/>
      </geometry>
      <origin xyz="0 0 0.02" rpy="0 0 0"/>
      <material name="white"><color rgba="0.9 0.9 0.9 1"/></material>
    </visual>
    <collision>
      <geometry>
        <cylinder length="0.04" radius="0.015"/>
      </geometry>
      <origin xyz="0 0 0.02" rpy="0 0 0"/>
    </collision>
    <inertial>
      <mass value="0.02"/>
      <origin xyz="0 0 0.02"/>
      <inertia ixx="0.00001" ixy="0" ixz="0" iyy="0.00001" iyz="0" izz="0.00001"/>
    </inertial>
  </link>
  <joint name="joint6" type="revolute">
    <parent link="link5"/>
    <child link="link6"/>
    <origin xyz="0 0 0.04" rpy="0 0 0"/>
    <axis xyz="0 1 0"/>
    <limit lower="-1.57" upper="1.57" effort="5" velocity="2"/>
  </joint>
  <link name="link6">
    <visual>
      <geometry>
        <cylinder length="0.04" radius="0.015"/>
      </geometry>
      <origin xyz="0 0 0.02" rpy="0 0 0"/>
      <material name="white"><color rgba="0.9 0.9 0.9 1"/></material>
    </visual>
    <collision>
      <geometry>
        <cylinder length="0.04" radius="0.015"/>
      </geometry>
      <origin xyz="0 0 0.02" rpy="0 0 0"/>
    </collision>
    <inertial>
      <mass value="0.02"/>
      <origin xyz="0 0 0.02"/>
      <inertia ixx="0.00001" ixy="0" ixz="0" iyy="0.00001" iyz="0" izz="0.00001"/>
    </inertial>
  </link>
  <joint name="joint7" type="revolute">
    <parent link="link6"/>
    <child link="link7"/>
    <origin xyz="0 0 0.04" rpy="0 0 0"/>
    <axis xyz="0 1 0"/>
    <limit lower="-1.57" upper="1.57" effort="5" velocity="2"/>
  </joint>
  <link name="link7">
    <visual>
      <geometry>
        <cylinder length="0.04" radius="0.015"/>
      </geometry>
      <origin xyz="0 0 0.02" rpy="0 0 0"/>
      <material name="white"><color rgba="0.9 0.9 0.9 1"/></material>
    </visual>
    <collision>
      <geometry>
        <cylinder length="0.04" radius="0.015"/>
      </geometry>
      <origin xyz="0 0 0.02" rpy="0 0 0"/>
    </collision>
    <inertial>
      <mass value="0.02"/>
      <origin xyz="0 0 0.02"/>
      <inertia ixx="0.00001" ixy="0" ixz="0" iyy="0.00001" iyz="0" izz="0.00001"/>
    </inertial>
  </link>
  <joint name="joint8" type="revolute">
    <parent link="link7"/>
    <child link="link8"/>
    <origin xyz="0 0 0.04" rpy="0 0 0"/>
    <axis xyz="0 1 0"/>
    <limit lower="-1.57" upper="1.57" effort="5" velocity="2"/>
  </joint>
  <link name="link8">
    <visual>
      <geometry>
        <cylinder length="0.04" radius="0.015"/>
      </geometry>
      <origin xyz="0 0 0.02" rpy="0